Workbook

Sheet Read me
A1: Attack-pet expansion: skills and equipment
A2: Single source of truth for the design. Edit the yellow cells; formulas (black) follow.
A4: What this is | B4: The design of the four attack pets' skill trees and of the shared pet equipment (monster drops with random blue options, Diablo 2 style). The server and client will be built from these tables.
A5: How to edit | B5: Yellow cells with blue text are design inputs: change them freely. Black cells are formulas (do not overwrite). To add a skill or an affix, insert a row inside its table and copy the formula cells from the row above.
A6: Sheets | B6: Rules: every global knob (points, rows, cooldown sharing, drop multipliers, blues). Pets: the four pets and their animations. Skills: all 60 skills (filter by Pet). Gear: equipment slots and base items by degree. Degrees: drop chance and blue odds per degree. Affixes: the blue option pool with tiers. Procs: the 'chance to cast' skills affixes and skills call.
A7: Status column | B7: Implemented = live in the lab build (wolf v1). Planned = designed, not built. Needs engine = also needs a new server mechanic (named in Engine notes).
A8: Skill rows | B8: Each pet has 2 active rows and 3 passive rows of 3 options. All learned actives in a row share one cooldown (using one puts the whole row on cooldown), so at most 2 actives fire independently. One passive per passive row is slotted at a time, so at most 3 passives are active.
A9: Cooldown kinds | B9: Timer (seconds), Attacks (pet attacks made), Hits taken (by the pet, or the owner where noted), Kills, Owner casts, Spells (pet spells cast). A counter cooldown keeps counting while the row waits.
A10: Ranks | B10: Every skill levels 1-10. Rank II (level 5) and Rank III (level 10) add an advanced option on top of the per-level growth (Rules sets the levels).
A11: Diablo 2 basis | B11: Magic items roll 1-2 affixes, rares 3+ (here capped at 5); one affix per group; each affix has a weight and a minimum item level; higher item level unlocks better tiers; procs come as 'on striking' and 'when struck'. Degree plays the part of item level.
A12: Open decisions | B12: 1) One equipment family worn by all pets in 3 slots (Collar, Harness, Charm) - confirm the 3 slots stay. 2) Passives are slotted one per row - confirm vs. all learned passives active. 3) Numbers are a first pass for balance testing.
A14: Changelog
A15: Date | B15: Change | C15: By
A16: 2026-10-14 | B16: First design: 4 pets x 5 rows x 3 skills, shared pet equipment with D1-D9 degrees, 5-blue cap, affix and proc pools. | C16: Claude (for owner review)

Sheet Rules
A1: Rules
A2: Global knobs. Other sheets read these cells by formula.
A4: Key | B4: Value | C4: Unit | D4: Meaning
A5: Skill max level | B5: 10 | C5: levels | D5: Every skill's level cap (a skill row may override).
A6: Rank II level | B6: 5 | C6: skill level | D6: Skill level that adds the Rank II option.
A7: Rank III level | B7: 10 | C7: skill level | D7: Skill level that adds the Rank III option.
A8: Pet levels per skill level | B8: 4 | C8: pet levels | D8: Each further skill level needs this many more pet levels than the last.
A9: Points per pet levels | B9: 3 | C9: pet levels | D9: One skill point at pet level 1, then one more every N levels.
A10: Option unlock step | B10: 5 | C10: pet levels | D10: Option 2 of a row unlocks this many levels after option 1, option 3 twice that.
A11: Row unlock: Active 1 | B11: 1 | C11: pet level | D11: First active row.
A12: Row unlock: Active 2 | B12: 20 | C12: pet level | D12: Second active row.
A13: Row unlock: Passive 1 | B13: 1 | C13: pet level
A14: Row unlock: Passive 2 | B14: 10 | C14: pet level
A15: Row unlock: Passive 3 | B15: 30 | C15: pet level
A16: Shared row cooldown | B16: Yes | D16: Using any active in a row puts the whole row on cooldown.
A17: Passives slotted per row | B17: 1 | C17: skills | D17: Passives active at once per passive row (3 rows = 3 passives).
A18: Proc internal cooldown | B18: 2 | C18: s | D18: A 'chance to cast' affix cannot fire twice within this time (D2 has none; we add it for balance).
A19: Max blues per item | B19: 5 | C19: options | D19: Hard cap on blue options per item.
A20: Magic: chance of 2 blues | B20: 0.4 | C20: fraction | D20: A magic item rolls 1 blue, or 2 with this chance.
A21: Monster rank x General | B21: 1 | C21: x | D21: Drop chance multiplier by monster rank.
A22: Monster rank x Champion | B22: 3 | C22: x
A23: Monster rank x Giant | B23: 8 | C23: x
A24: Monster rank x Unique | B24: 100 | C24: x | D24: Uniques also drop one degree higher (capped at D9).
A25: Collar implicit per degree | B25: 2 | C25: % damage | D25: Base (white) stat of a collar: damage +N% per degree.
A26: Harness implicit per degree | B26: 3 | C26: % defense | D26: Base stat of a harness: defense +N% per degree.
A27: Charm implicit per degree | B27: 1 | C27: % cooldown | D27: Base stat of a charm: skill cooldowns -N% per degree.
A28: Drop source | B28: Monsters | D28: Pet equipment drops from monsters only; no NPC shop sells it.
A30: Skill points at pet level
A31: Pet level | B31: Points (formula)
A32: 1 | B32: =1+INT(A32/Rules!$B$9) -> 1
A33: 17 | B33: =1+INT(A33/Rules!$B$9) -> 6
A34: 30 | B34: =1+INT(A34/Rules!$B$9) -> 11
A35: 60 | B35: =1+INT(A35/Rules!$B$9) -> 21
A36: 90 | B36: =1+INT(A36/Rules!$B$9) -> 31
A37: 140 | B37: =1+INT(A37/Rules!$B$9) -> 47
A38: One skill per row maxed needs 5 x 10 = 50 points: a choice even at level 140.

Sheet Pets
A1: Pets
A2: The four attack pets (v1.150 data: 140 levels each) and the native animation clips their skills can use.
A4: Pet | B4: Role | C4: Codename family | D4: Summon item | E4: Leans on | F4: Model clips | G4: Active animation | H4: Notes
A5: Bear | B5: Defense | C5: COS_P_BEAR | D5: ITEM_COS_P_BEAR_SCROLL | E5: HP, defense, threat | F5: stand, walk, run, attack1, hit1, down, wakeup, emote0 (roar) | G5: emote0 for roars and taunts; attack1 for slams | H5: Tank: holds monsters off the owner.
A6: Wolf | B6: Attack | C6: COS_P_WOLF, _WHITE, _WHITE_SMALL | D6: ITEM_COS_P_FLUTE (+_WHITE, _WHITE_SMALL) | E6: Physical damage, speed | F6: stand, walk, run, attack1, down, wakeup, emote0 (howl) | G6: emote0 for howls; attack1 for bites | H6: Damage dealer; current lab build has the v1 wolf tree.
A7: Penguin | B7: Magic | C7: COS_P_PENGUIN | D7: ITEM_COS_P_PENGUIN_SCROLL | E7: Magic damage, frost control | F7: stand, walk, run, attack1, attack2, hit1, down, emote0 | G7: attack2 for spells; emote0 for wards | H7: Only pet with a second attack clip: spells read as casts.
A8: Crow | B8: Support | C8: COS_P_RAVEN | D8: ITEM_COS_P_RAVEN_SCROLL | E8: Owner and party buffs | F8: stand, walk, run, attack1, hit1, down, emote0 (caw) | G8: emote0 for cries; attack1 for pecks | H8: The native raven model.

Sheet Skills
A1: Skills
A2: Each pet: 2 active rows + 3 passive rows, 3 options each. {v} in an effect is the Value column at the skill's level.
A4: Pet | B4: Row | C4: Row theme | D4: Option | E4: Skill | F4: Effect ({v}) | G4: Trigger / cooldown kind | H4: Cooldown L1 | I4: Cooldown unit | J4: Cooldown per level | K4: Value L1 | L4: Value per level | M4: Value unit | N4: Max level | O4: Value at max | P4: Cooldown at max | Q4: Rank II | R4: Rank III | S4: Unlock pet level | T4: Pet level for max | U4: Animation | V4: Engine notes | W4: Status | X4: ID | Y4: Icon
A5: Wolf | B5: Active 1 | C5: Control | D5: 1 | E5: Terrifying Howl | F5: Howls: up to {v} monsters within 6 m are terrified for 3 s and cannot attack the wolf. | G5: Timer | H5: 25 | I5: s | J5: -0.5 | K5: 3 | L5: 0.5 | M5: monsters | N5: =Rules!$B$5 -> 10 | O5: =K5+L5*(N5-1) -> 7.5 | P5: =IF(H5="","",H5+IF(J5="",0,J5)*(N5-1)) -> 20.5 | Q5: Radius 9 m. | R5: Terror lasts 4 s. | S5: =INDEX(Rules!$B$11:$B$15,MATCH("Row unlock: "&B5,Rules!$A$11:$A$15,0))+(D5-1)*Rules!$B$10 -> 1 | T5: =S5+(N5-1)*Rules!$B$8 -> 37 | U5: emote0 | V5: Live (native Fear: feared monsters cannot attack the pet), Rank II and III live. | W5: Implemented | X5: 1 | Y5: skill\europe\warrior_twohanda_cry_a
A6: Wolf | B6: Active 1 | C6: Control | D6: 2 | E6: Hamstring | F6: Bites the legs: the target is stunned {v} s. | G6: Attacks | H6: 12 | I6: attacks | J6: -0.5 | K6: 1 | L6: 0.15 | M6: s | N6: =Rules!$B$5 -> 10 | O6: =K6+L6*(N6-1) -> 2.35 | P6: =IF(H6="","",H6+IF(J6="",0,J6)*(N6-1)) -> 7.5 | Q6: After the stun the target is slowed 40% for 4 s. | R6: The stun also hits 2 enemies next to the target. | S6: =INDEX(Rules!$B$11:$B$15,MATCH("Row unlock: "&B6,Rules!$A$11:$A$15,0))+(D6-1)*Rules!$B$10 -> 6 | T6: =S6+(N6-1)*Rules!$B$8 -> 42 | U6: attack1 | V6: Live (native stun). Rank III live; Rank II slow planned. | W6: Implemented | X6: 2 | Y6: skill\europe\warlock_soula_stun_a
A7: Wolf | B7: Active 1 | C7: Control | D7: 3 | E7: Alpha's Lure | F7: Up to {v} monsters within 12 m must chase the wolf for 5 s. | G7: Kills | H7: 4 | I7: kills | J7: -0.2 | K7: 2 | L7: 0.4 | M7: monsters | N7: =Rules!$B$5 -> 10 | O7: =K7+L7*(N7-1) -> 5.6 | P7: =IF(H7="","",H7+IF(J7="",0,J7)*(N7-1)) -> 2.2 | Q7: Lured monsters are pulled to the wolf. | R7: The owner deals +20% damage to lured monsters. | S7: =INDEX(Rules!$B$11:$B$15,MATCH("Row unlock: "&B7,Rules!$A$11:$A$15,0))+(D7-1)*Rules!$B$10 -> 11 | T7: =S7+(N7-1)*Rules!$B$8 -> 47 | U7: emote0 | V7: Threat override in monster AI; displacement exists. | W7: Needs engine | X7: 3 | Y7: skill\europe\warrior_frenzya_tount_a
A8: Wolf | B8: Active 2 | C8: Burst | D8: 1 | E8: Rending Bite | F8: Bites for {v}% damage; the target bleeds 2 x pet level every 2 s for 6 s. | G8: Timer | H8: 12 | I8: s | J8: -0.3 | K8: 120 | L8: 5 | M8: % damage | N8: =Rules!$B$5 -> 10 | O8: =K8+L8*(N8-1) -> 165 | P8: =IF(H8="","",H8+IF(J8="",0,J8)*(N8-1)) -> 9.3 | Q8: Bleed stacks twice. | R8: Bleeding targets below 30% HP are killed outright (not bosses). | S8: =INDEX(Rules!$B$11:$B$15,MATCH("Row unlock: "&B8,Rules!$A$11:$A$15,0))+(D8-1)*Rules!$B$10 -> 20 | T8: =S8+(N8-1)*Rules!$B$8 -> 56 | U8: attack1 | V8: Live (native bleed). Rank II and III live. | W8: Implemented | X8: 4 | Y8: skill\china\fire_gigongta_b
A9: Wolf | B9: Active 2 | C9: Burst | D9: 2 | E9: Frenzy | F9: Attack speed +{v}% for 6 s. | G9: Attacks | H9: 20 | I9: attacks | J9: -1 | K9: 25 | L9: 3 | M9: % speed | N9: =Rules!$B$5 -> 10 | O9: =K9+L9*(N9-1) -> 52 | P9: =IF(H9="","",H9+IF(J9="",0,J9)*(N9-1)) -> 11 | Q9: +15% critical chance while frenzied. | R9: Every kill while frenzied adds 2 s. | S9: =INDEX(Rules!$B$11:$B$15,MATCH("Row unlock: "&B9,Rules!$A$11:$A$15,0))+(D9-1)*Rules!$B$10 -> 25 | T9: =S9+(N9-1)*Rules!$B$8 -> 61 | U9: emote0 | V9: Live (attack interval). Rank II live; Rank III planned. | W9: Implemented | X9: 5 | Y9: skill\europe\warrior_frenzya_damage_a
A10: Wolf | B10: Active 2 | C10: Burst | D10: 3 | E10: Pounce | F10: Leaps at a target up to 10 m away for {v}% damage. | G10: Timer | H10: 18 | I10: s | J10: -0.5 | K10: 140 | L10: 6 | M10: % damage | N10: =Rules!$B$5 -> 10 | O10: =K10+L10*(N10-1) -> 194 | P10: =IF(H10="","",H10+IF(J10="",0,J10)*(N10-1)) -> 13.5 | Q10: Knocks the target down for 2 s. | R10: Lands with a 3 m splash for 50% to others. | S10: =INDEX(Rules!$B$11:$B$15,MATCH("Row unlock: "&B10,Rules!$A$11:$A$15,0))+(D10-1)*Rules!$B$10 -> 30 | T10: =S10+(N10-1)*Rules!$B$8 -> 66 | U10: attack1 | V10: Live as the fight's opening hit (no leap). Rank II and III live. | W10: Implemented | X10: 6 | Y10: skill\china\bow_call_b
A11: Wolf | B11: Passive 1 | C11: Killer instinct | D11: 1 | E11: Execute | F11: Kills non-boss monsters below {v}% HP outright. | G11: Passive | K11: 5 | L11: 0.7 | M11: % HP | N11: =Rules!$B$5 -> 10 | O11: =K11+L11*(N11-1) -> 11.3 | P11: =IF(H11="","",H11+IF(J11="",0,J11)*(N11-1)) | Q11: +5% threshold against bleeding targets. | R11: An execution heals the wolf 10% and takes 3 s off the Burst row. | S11: =INDEX(Rules!$B$11:$B$15,MATCH("Row unlock: "&B11,Rules!$A$11:$A$15,0))+(D11-1)*Rules!$B$10 -> 1 | T11: =S11+(N11-1)*Rules!$B$8 -> 37 | U11: attack1 | V11: Live. Rank II live; Rank III planned. | W11: Implemented | X11: 7 | Y11: skill\europe\warrior_onehanda_critical_a
A12: Wolf | B12: Passive 1 | C12: Killer instinct | D12: 2 | E12: Bloodlust | F12: Every 10th attack deals {v}% damage. | G12: Attacks | H12: 10 | I12: attacks | J12: 0 | K12: 250 | L12: 17 | M12: % damage | N12: =Rules!$B$5 -> 10 | O12: =K12+L12*(N12-1) -> 403 | P12: =IF(H12="","",H12+IF(J12="",0,J12)*(N12-1)) -> 10 | Q12: Every 8th attack instead. | R12: The strike cleaves everything within 3 m. | S12: =INDEX(Rules!$B$11:$B$15,MATCH("Row unlock: "&B12,Rules!$A$11:$A$15,0))+(D12-1)*Rules!$B$10 -> 6 | T12: =S12+(N12-1)*Rules!$B$8 -> 42 | U12: attack1 | V12: Live. Rank II and III live. | W12: Implemented | X12: 8 | Y12: skill\europe\warlock_blooda_explosion_a
A13: Wolf | B13: Passive 1 | C13: Killer instinct | D13: 3 | E13: Predator | F13: +{v}% physical attack. | G13: Passive | K13: 3 | L13: 3 | M13: % attack | N13: =Rules!$B$5 -> 10 | O13: =K13+L13*(N13-1) -> 30 | P13: =IF(H13="","",H13+IF(J13="",0,J13)*(N13-1)) | Q13: +10% critical damage. | R13: The owner gets +5% attack while the wolf lives. | S13: =INDEX(Rules!$B$11:$B$15,MATCH("Row unlock: "&B13,Rules!$A$11:$A$15,0))+(D13-1)*Rules!$B$10 -> 11 | T13: =S13+(N13-1)*Rules!$B$8 -> 47 | V13: Live. Ranks II and III planned. | W13: Implemented | X13: 9 | Y13: skill\china\lightning_chundung_b
A14: Wolf | B14: Passive 2 | C14: Pack | D14: 1 | E14: Pack Runner | F14: Wolf movement speed +{v}%. | G14: Passive | K14: 4 | L14: 1.2 | M14: % speed | N14: =Rules!$B$5 -> 10 | O14: =K14+L14*(N14-1) -> 14.8 | P14: =IF(H14="","",H14+IF(J14="",0,J14)*(N14-1)) | Q14: The owner gets half the bonus. | R14: Every party member within 20 m gets the full bonus (one Pack Runner counts). | S14: =INDEX(Rules!$B$11:$B$15,MATCH("Row unlock: "&B14,Rules!$A$11:$A$15,0))+(D14-1)*Rules!$B$10 -> 10 | T14: =S14+(N14-1)*Rules!$B$8 -> 46 | V14: Movement speed parameter on pet, owner and party. | W14: Planned | X14: 10 | Y14: skill\europe\rog_stealthp_mspeed_a
A15: Wolf | B15: Passive 2 | C15: Pack | D15: 2 | E15: Scent of Blood | F15: +{v}% critical chance against bleeding or wounded (below 50%) targets. | G15: Passive | K15: 3 | L15: 1 | M15: % crit | N15: =Rules!$B$5 -> 10 | O15: =K15+L15*(N15-1) -> 12 | P15: =IF(H15="","",H15+IF(J15="",0,J15)*(N15-1)) | Q15: Critical hits refresh the bleed. | R15: Critical hits heal the wolf 2%. | S15: =INDEX(Rules!$B$11:$B$15,MATCH("Row unlock: "&B15,Rules!$A$11:$A$15,0))+(D15-1)*Rules!$B$10 -> 15 | T15: =S15+(N15-1)*Rules!$B$8 -> 51 | V15: Live. Ranks II and III planned. | W15: Implemented | X15: 11 | Y15: skill\europe\warlock_dota_blooding_a
A16: Wolf | B16: Passive 2 | C16: Pack | D16: 3 | E16: Swift Fangs | F16: +{v}% attack speed. | G16: Passive | K16: 2 | L16: 1.5 | M16: % speed | N16: =Rules!$B$5 -> 10 | O16: =K16+L16*(N16-1) -> 15.5 | P16: =IF(H16="","",H16+IF(J16="",0,J16)*(N16-1)) | Q16: +5% movement speed. | R16: Every 5th attack strikes twice. | S16: =INDEX(Rules!$B$11:$B$15,MATCH("Row unlock: "&B16,Rules!$A$11:$A$15,0))+(D16-1)*Rules!$B$10 -> 20 | T16: =S16+(N16-1)*Rules!$B$8 -> 56 | V16: Live (attack interval). Ranks II and III planned. | W16: Implemented | X16: 12 | Y16: skill\europe\rog_daggera_speed_a
A17: Wolf | B17: Passive 3 | C17: Survival | D17: 1 | E17: Thick Fur | F17: +{v}% physical and magical defense. | G17: Passive | K17: 3 | L17: 2 | M17: % defense | N17: =Rules!$B$5 -> 10 | O17: =K17+L17*(N17-1) -> 21 | P17: =IF(H17="","",H17+IF(J17="",0,J17)*(N17-1)) | Q17: +5% parry. | R17: +10% status resistance. | S17: =INDEX(Rules!$B$11:$B$15,MATCH("Row unlock: "&B17,Rules!$A$11:$A$15,0))+(D17-1)*Rules!$B$10 -> 30 | T17: =S17+(N17-1)*Rules!$B$8 -> 66 | V17: Live. Ranks II and III planned. | W17: Implemented | X17: 13 | Y17: skill\europe\warrior_shieldp_defense_a
A18: Wolf | B18: Passive 3 | C18: Survival | D18: 2 | E18: Lifebite | F18: {v}% of damage dealt heals the wolf. | G18: Passive | K18: 2 | L18: 0.6 | M18: % leech | N18: =Rules!$B$5 -> 10 | O18: =K18+L18*(N18-1) -> 7.4 | P18: =IF(H18="","",H18+IF(J18="",0,J18)*(N18-1)) | Q18: The owner is healed half as much. | R18: Healing above full HP becomes a 10 s shield. | S18: =INDEX(Rules!$B$11:$B$15,MATCH("Row unlock: "&B18,Rules!$A$11:$A$15,0))+(D18-1)*Rules!$B$10 -> 35 | T18: =S18+(N18-1)*Rules!$B$8 -> 71 | V18: Live. Ranks II and III planned. | W18: Implemented | X18: 14 | Y18: skill\europe\warlock_blooda_lifedrain_a
A19: Wolf | B19: Passive 3 | C19: Survival | D19: 3 | E19: Second Wind | F19: Below 30% HP the wolf heals {v}% of its max HP. | G19: Timer | H19: 90 | I19: s | J19: -3 | K19: 15 | L19: 2 | M19: % HP | N19: =Rules!$B$5 -> 10 | O19: =K19+L19*(N19-1) -> 33 | P19: =IF(H19="","",H19+IF(J19="",0,J19)*(N19-1)) -> 63 | Q19: Also clears one harmful status. | R19: Also heals the owner the same amount. | S19: =INDEX(Rules!$B$11:$B$15,MATCH("Row unlock: "&B19,Rules!$A$11:$A$15,0))+(D19-1)*Rules!$B$10 -> 40 | T19: =S19+(N19-1)*Rules!$B$8 -> 76 | U19: emote0 | V19: Live (checked on the wolf's next attack). Ranks II and III planned. | W19: Implemented | X19: 15 | Y19: skill\europe\cleric_recoverya_quick_a
A20: Bear | B20: Active 1 | C20: Threat | D20: 1 | E20: Challenging Roar | F20: Taunts up to {v} monsters within 8 m for 6 s. | G20: Timer | H20: 18 | I20: s | J20: -0.5 | K20: 3 | L20: 0.5 | M20: monsters | N20: =Rules!$B$5 -> 10 | O20: =K20+L20*(N20-1) -> 7.5 | P20: =IF(H20="","",H20+IF(J20="",0,J20)*(N20-1)) -> 13.5 | Q20: Taunted monsters deal 15% less damage. | R20: Radius 12 m; uniques are taunted for 3 s. | S20: =INDEX(Rules!$B$11:$B$15,MATCH("Row unlock: "&B20,Rules!$A$11:$A$15,0))+(D20-1)*Rules!$B$10 -> 1 | T20: =S20+(N20-1)*Rules!$B$8 -> 37 | U20: emote0 | V20: Threat override in monster AI. | W20: Needs engine | X20: 16 | Y20: skill\europe\warrior_frenzya_tount_area_a
A21: Bear | B21: Active 1 | C21: Threat | D21: 2 | E21: Ground Slam | F21: Stuns up to {v} monsters within 4 m for 1.5 s. | G21: Hits taken | H21: 15 | I21: hits taken | J21: -0.5 | K21: 2 | L21: 0.4 | M21: monsters | N21: =Rules!$B$5 -> 10 | O21: =K21+L21*(N21-1) -> 5.6 | P21: =IF(H21="","",H21+IF(J21="",0,J21)*(N21-1)) -> 10.5 | Q21: Stun lasts 2.5 s. | R21: An aftershock 2 s later deals 100% damage. | S21: =INDEX(Rules!$B$11:$B$15,MATCH("Row unlock: "&B21,Rules!$A$11:$A$15,0))+(D21-1)*Rules!$B$10 -> 6 | T21: =S21+(N21-1)*Rules!$B$8 -> 42 | U21: attack1 | V21: Live (native stun, area around the bear). Rank II live; Rank III planned. | W21: Implemented | X21: 17 | Y21: skill\europe\wizard_eartha_area_a
A22: Bear | B22: Active 1 | C22: Threat | D22: 3 | E22: Bear Hug | F22: Drags one monster from up to 15 m to the bear and holds it {v} s. | G22: Timer | H22: 15 | I22: s | J22: -0.4 | K22: 2 | L22: 0.2 | M22: s | N22: =Rules!$B$5 -> 10 | O22: =K22+L22*(N22-1) -> 3.8 | P22: =IF(H22="","",H22+IF(J22="",0,J22)*(N22-1)) -> 11.4 | Q22: Pulls up to 3 monsters. | R22: The held monster takes +25% damage. | S22: =INDEX(Rules!$B$11:$B$15,MATCH("Row unlock: "&B22,Rules!$A$11:$A$15,0))+(D22-1)*Rules!$B$10 -> 11 | T22: =S22+(N22-1)*Rules!$B$8 -> 47 | U22: attack1 | V22: Displacement exists; hold = stun. | W22: Planned | X22: 18 | Y22: skill\europe\warrior_guarda_intercept_a
A23: Bear | B23: Active 2 | C23: Endurance | D23: 1 | E23: Retribution | F23: Stores {v}% of damage taken for 10 s, then releases it at everything within 5 m. | G23: Hits taken | H23: 30 | I23: hits taken | J23: -1 | K23: 60 | L23: 8 | M23: % stored | N23: =Rules!$B$5 -> 10 | O23: =K23+L23*(N23-1) -> 132 | P23: =IF(H23="","",H23+IF(J23="",0,J23)*(N23-1)) -> 21 | Q23: Also heals the bear 25% of the stored damage. | R23: The release stuns for 2 s. | S23: =INDEX(Rules!$B$11:$B$15,MATCH("Row unlock: "&B23,Rules!$A$11:$A$15,0))+(D23-1)*Rules!$B$10 -> 20 | T23: =S23+(N23-1)*Rules!$B$8 -> 56 | U23: emote0 | V23: Live (released on the bear's next attack after 10 s). Rank III live; Rank II planned. | W23: Implemented | X23: 19 | Y23: skill\europe\warrior_twohandp_return_a
A24: Bear | B24: Active 2 | C24: Endurance | D24: 2 | E24: Iron Hide | F24: Damage taken -{v}% for 6 s. | G24: Timer | H24: 30 | I24: s | J24: -1 | K24: 30 | L24: 2.5 | M24: % reduced | N24: =Rules!$B$5 -> 10 | O24: =K24+L24*(N24-1) -> 52.5 | P24: =IF(H24="","",H24+IF(J24="",0,J24)*(N24-1)) -> 21 | Q24: Immune to knockdown while active. | R24: The owner gets half the reduction. | S24: =INDEX(Rules!$B$11:$B$15,MATCH("Row unlock: "&B24,Rules!$A$11:$A$15,0))+(D24-1)*Rules!$B$10 -> 25 | T24: =S24+(N24-1)*Rules!$B$8 -> 61 | U24: emote0 | V24: Live (triggers below 70% HP). Ranks II and III planned. | W24: Implemented | X24: 20 | Y24: skill\europe\warrior_guarda_physical_a
A25: Bear | B25: Active 2 | C25: Endurance | D25: 3 | E25: Guardian Bond | F25: Takes {v}% of the owner's damage for 10 s. | G25: Timer | H25: 40 | I25: s | J25: -1 | K25: 20 | L25: 2 | M25: % redirected | N25: =Rules!$B$5 -> 10 | O25: =K25+L25*(N25-1) -> 38 | P25: =IF(H25="","",H25+IF(J25="",0,J25)*(N25-1)) -> 31 | Q25: The bear's defense applies to the redirected damage. | R25: Covers party members within 10 m. | S25: =INDEX(Rules!$B$11:$B$15,MATCH("Row unlock: "&B25,Rules!$A$11:$A$15,0))+(D25-1)*Rules!$B$10 -> 30 | T25: =S25+(N25-1)*Rules!$B$8 -> 66 | U25: emote0 | V25: Damage redirect on the player victim path. | W25: Needs engine | X25: 21 | Y25: skill\europe\warrior_guarda_divide_a
A26: Bear | B26: Passive 1 | C26: Hide | D26: 1 | E26: Thick Hide | F26: +{v}% physical and magical defense. | G26: Passive | K26: 4 | L26: 2 | M26: % defense | N26: =Rules!$B$5 -> 10 | O26: =K26+L26*(N26-1) -> 22 | P26: =IF(H26="","",H26+IF(J26="",0,J26)*(N26-1)) | Q26: +5% block. | R26: +10% status resistance. | S26: =INDEX(Rules!$B$11:$B$15,MATCH("Row unlock: "&B26,Rules!$A$11:$A$15,0))+(D26-1)*Rules!$B$10 -> 1 | T26: =S26+(N26-1)*Rules!$B$8 -> 37 | V26: Live. Ranks II and III planned. | W26: Implemented | X26: 22 | Y26: skill\china\cold_ganggi_b
A27: Bear | B27: Passive 1 | C27: Hide | D27: 2 | E27: Fortitude | F27: +{v}% max HP. | G27: Passive | K27: 5 | L27: 2.5 | M27: % HP | N27: =Rules!$B$5 -> 10 | O27: =K27+L27*(N27-1) -> 27.5 | P27: =IF(H27="","",H27+IF(J27="",0,J27)*(N27-1)) | Q27: +1% HP regeneration every 2 s. | R27: Revives once per 10 min at 30% HP. | S27: =INDEX(Rules!$B$11:$B$15,MATCH("Row unlock: "&B27,Rules!$A$11:$A$15,0))+(D27-1)*Rules!$B$10 -> 6 | T27: =S27+(N27-1)*Rules!$B$8 -> 42 | W27: Planned | X27: 23 | Y27: skill\europe\warrior_frenzya_health_a
A28: Bear | B28: Passive 1 | C28: Hide | D28: 3 | E28: Thorns | F28: Attackers take {v}% of their damage back. | G28: Passive | K28: 10 | L28: 4 | M28: % returned | N28: =Rules!$B$5 -> 10 | O28: =K28+L28*(N28-1) -> 46 | P28: =IF(H28="","",H28+IF(J28="",0,J28)*(N28-1)) | Q28: Returned damage can stun (5%). | R28: Also covers hits on the owner. | S28: =INDEX(Rules!$B$11:$B$15,MATCH("Row unlock: "&B28,Rules!$A$11:$A$15,0))+(D28-1)*Rules!$B$10 -> 11 | T28: =S28+(N28-1)*Rules!$B$8 -> 47 | V28: Damage return exists for players (damagereturn.go). | W28: Planned | X28: 24 | Y28: skill\europe\warlock_soula_return_a
A29: Bear | B29: Passive 2 | C29: Steadfast | D29: 1 | E29: Last Stand | F29: Below 30% HP: defense +{v}%. | G29: Passive | K29: 10 | L29: 3 | M29: % defense | N29: =Rules!$B$5 -> 10 | O29: =K29+L29*(N29-1) -> 37 | P29: =IF(H29="","",H29+IF(J29="",0,J29)*(N29-1)) | Q29: Threshold 40% HP. | R29: Taunts everything within 6 m when it triggers (60 s cooldown). | S29: =INDEX(Rules!$B$11:$B$15,MATCH("Row unlock: "&B29,Rules!$A$11:$A$15,0))+(D29-1)*Rules!$B$10 -> 10 | T29: =S29+(N29-1)*Rules!$B$8 -> 46 | V29: Live. Ranks II and III planned. | W29: Implemented | X29: 25 | Y29: skill\china\fire_ganggi_b
A30: Bear | B30: Passive 2 | C30: Steadfast | D30: 2 | E30: Unshakable | F30: {v}% chance to ignore knockdown, stun and freeze. | G30: Passive | K30: 10 | L30: 4 | M30: % chance | N30: =Rules!$B$5 -> 10 | O30: =K30+L30*(N30-1) -> 46 | P30: =IF(H30="","",H30+IF(J30="",0,J30)*(N30-1)) | Q30: Also ignores slows. | R30: Gives the owner half the chance. | S30: =INDEX(Rules!$B$11:$B$15,MATCH("Row unlock: "&B30,Rules!$A$11:$A$15,0))+(D30-1)*Rules!$B$10 -> 15 | T30: =S30+(N30-1)*Rules!$B$8 -> 51 | V30: Status resistance roll exists. | W30: Planned | X30: 26 | Y30: skill\europe\warrior_dualp_abnormal_a
A31: Bear | B31: Passive 2 | C31: Steadfast | D31: 3 | E31: Regeneration | F31: Regenerates {v}% max HP every 2 s out of combat (half in combat). | G31: Passive | K31: 1 | L31: 0.3 | M31: % HP | N31: =Rules!$B$5 -> 10 | O31: =K31+L31*(N31-1) -> 3.7 | P31: =IF(H31="","",H31+IF(J31="",0,J31)*(N31-1)) | Q31: Full rate in combat. | R31: Also regenerates the owner. | S31: =INDEX(Rules!$B$11:$B$15,MATCH("Row unlock: "&B31,Rules!$A$11:$A$15,0))+(D31-1)*Rules!$B$10 -> 20 | T31: =S31+(N31-1)*Rules!$B$8 -> 56 | W31: Planned | X31: 27 | Y31: skill\europe\cleric_recoverya_target_a
A32: Bear | B32: Passive 3 | C32: Protector | D32: 1 | E32: Bodyguard | F32: When the owner is hit, {v}% chance the bear taunts that monster. | G32: Passive | K32: 20 | L32: 6 | M32: % chance | N32: =Rules!$B$5 -> 10 | O32: =K32+L32*(N32-1) -> 74 | P32: =IF(H32="","",H32+IF(J32="",0,J32)*(N32-1)) | Q32: Taunted monster is slowed 20%. | R32: Works for the whole party within 10 m. | S32: =INDEX(Rules!$B$11:$B$15,MATCH("Row unlock: "&B32,Rules!$A$11:$A$15,0))+(D32-1)*Rules!$B$10 -> 30 | T32: =S32+(N32-1)*Rules!$B$8 -> 66 | V32: Threat override. | W32: Needs engine | X32: 28 | Y32: skill\europe\warrior_guarda_aggro_a
A33: Bear | B33: Passive 3 | C33: Protector | D33: 2 | E33: Crushing Paw | F33: Every 6th attack stuns the target for {v} s. | G33: Attacks | H33: 6 | I33: attacks | J33: 0 | K33: 0.8 | L33: 0.12 | M33: s | N33: =Rules!$B$5 -> 10 | O33: =K33+L33*(N33-1) -> 1.88 | P33: =IF(H33="","",H33+IF(J33="",0,J33)*(N33-1)) -> 6 | Q33: Every 5th attack. | R33: The stun hits all within 3 m. | S33: =INDEX(Rules!$B$11:$B$15,MATCH("Row unlock: "&B33,Rules!$A$11:$A$15,0))+(D33-1)*Rules!$B$10 -> 35 | T33: =S33+(N33-1)*Rules!$B$8 -> 71 | U33: attack1 | V33: Live (native stun). Rank II and III live. | W33: Implemented | X33: 29 | Y33: skill\europe\warrior_duala_stun_a
A34: Bear | B34: Passive 3 | C34: Protector | D34: 3 | E34: Steadfast Aura | F34: Owner defense +{v}%. | G34: Passive | K34: 3 | L34: 1 | M34: % defense | N34: =Rules!$B$5 -> 10 | O34: =K34+L34*(N34-1) -> 12 | P34: =IF(H34="","",H34+IF(J34="",0,J34)*(N34-1)) | Q34: Also +5% max HP to the owner. | R34: Whole party within 20 m. | S34: =INDEX(Rules!$B$11:$B$15,MATCH("Row unlock: "&B34,Rules!$A$11:$A$15,0))+(D34-1)*Rules!$B$10 -> 40 | T34: =S34+(N34-1)*Rules!$B$8 -> 76 | V34: Owner/party stat aura. | W34: Planned | X34: 30 | Y34: skill\europe\warrior_guarda_all_block_a
A35: Penguin | B35: Active 1 | C35: Frost spells | D35: 1 | E35: Frost Nova | F35: Ice blast: {v}% magic damage to everything within 5 m, frostbite 3 s. | G35: Timer | H35: 14 | I35: s | J35: -0.4 | K35: 120 | L35: 12 | M35: % damage | N35: =Rules!$B$5 -> 10 | O35: =K35+L35*(N35-1) -> 228 | P35: =IF(H35="","",H35+IF(J35="",0,J35)*(N35-1)) -> 10.4 | Q35: Radius 7 m. | R35: Frozen targets shatter for 50% extra damage. | S35: =INDEX(Rules!$B$11:$B$15,MATCH("Row unlock: "&B35,Rules!$A$11:$A$15,0))+(D35-1)*Rules!$B$10 -> 1 | T35: =S35+(N35-1)*Rules!$B$8 -> 37 | U35: attack2 | V35: Live (native frostbite, area around the penguin). Rank II live; Rank III planned. | W35: Implemented | X35: 31 | Y35: skill\europe\wizard_colda_area_a
A36: Penguin | B36: Active 1 | C36: Frost spells | D36: 2 | E36: Blizzard | F36: Ice storm on the target: {v}% magic damage per second for 4 s within 4 m. | G36: Timer | H36: 20 | I36: s | J36: -0.5 | K36: 45 | L36: 5 | M36: % per s | N36: =Rules!$B$5 -> 10 | O36: =K36+L36*(N36-1) -> 90 | P36: =IF(H36="","",H36+IF(J36="",0,J36)*(N36-1)) -> 15.5 | Q36: Slows 40% inside the storm. | R36: Lasts 6 s. | S36: =INDEX(Rules!$B$11:$B$15,MATCH("Row unlock: "&B36,Rules!$A$11:$A$15,0))+(D36-1)*Rules!$B$10 -> 6 | T36: =S36+(N36-1)*Rules!$B$8 -> 42 | U36: attack2 | V36: Ground effect with pulses (traps exist). | W36: Planned | X36: 32 | Y36: skill\europe\wizard_colda_area_b
A37: Penguin | B37: Active 1 | C37: Frost spells | D37: 3 | E37: Ice Slide | F37: Slides through a 10 m line for {v}% damage, chilling everything hit. | G37: Attacks | H37: 10 | I37: attacks | J37: -0.4 | K37: 150 | L37: 10 | M37: % damage | N37: =Rules!$B$5 -> 10 | O37: =K37+L37*(N37-1) -> 240 | P37: =IF(H37="","",H37+IF(J37="",0,J37)*(N37-1)) -> 6.4 | Q37: Leaves an ice trail that slows. | R37: Slides back for a second hit. | S37: =INDEX(Rules!$B$11:$B$15,MATCH("Row unlock: "&B37,Rules!$A$11:$A$15,0))+(D37-1)*Rules!$B$10 -> 11 | T37: =S37+(N37-1)*Rules!$B$8 -> 47 | U37: run | V37: Movement burst + line candidates. | W37: Planned | X37: 33 | Y37: skill\europe\wizard_colda_point_a
A38: Penguin | B38: Active 2 | C38: Control | D38: 1 | E38: Deep Freeze | F38: Freezes one target for {v} s (bosses are slowed instead). | G38: Timer | H38: 16 | I38: s | J38: -0.4 | K38: 2 | L38: 0.2 | M38: s | N38: =Rules!$B$5 -> 10 | O38: =K38+L38*(N38-1) -> 3.8 | P38: =IF(H38="","",H38+IF(J38="",0,J38)*(N38-1)) -> 12.4 | Q38: Spreads to 2 more targets. | R38: Frozen targets take +20% from everyone. | S38: =INDEX(Rules!$B$11:$B$15,MATCH("Row unlock: "&B38,Rules!$A$11:$A$15,0))+(D38-1)*Rules!$B$10 -> 20 | T38: =S38+(N38-1)*Rules!$B$8 -> 56 | U38: attack2 | V38: Live (native freeze). Rank II live; Rank III planned. | W38: Implemented | X38: 34 | Y38: skill\europe\wizard_colda_point_b
A39: Penguin | B39: Active 2 | C39: Control | D39: 2 | E39: Glacial Ward | F39: Ice shield on the owner absorbs {v}% of the owner's max HP for 8 s. | G39: Hits taken | H39: 20 | I39: owner hits taken | J39: -0.5 | K39: 8 | L39: 1.5 | M39: % owner HP | N39: =Rules!$B$5 -> 10 | O39: =K39+L39*(N39-1) -> 21.5 | P39: =IF(H39="","",H39+IF(J39="",0,J39)*(N39-1)) -> 15.5 | Q39: Reflects 30% of absorbed damage as cold. | R39: Party within 8 m get half the shield. | S39: =INDEX(Rules!$B$11:$B$15,MATCH("Row unlock: "&B39,Rules!$A$11:$A$15,0))+(D39-1)*Rules!$B$10 -> 25 | T39: =S39+(N39-1)*Rules!$B$8 -> 61 | U39: emote0 | V39: Absorb shield exists for players (skills). | W39: Planned | X39: 35 | Y39: skill\europe\wizard_eartha_guard_a
A40: Penguin | B40: Active 2 | C40: Control | D40: 3 | E40: Mana Spring | F40: Restores {v}% of the owner's max MP. | G40: Owner casts | H40: 15 | I40: owner casts | J40: -0.5 | K40: 5 | L40: 1 | M40: % MP | N40: =Rules!$B$5 -> 10 | O40: =K40+L40*(N40-1) -> 14 | P40: =IF(H40="","",H40+IF(J40="",0,J40)*(N40-1)) -> 10.5 | Q40: Also restores half as much HP. | R40: The owner's next skill costs no MP. | S40: =INDEX(Rules!$B$11:$B$15,MATCH("Row unlock: "&B40,Rules!$A$11:$A$15,0))+(D40-1)*Rules!$B$10 -> 30 | T40: =S40+(N40-1)*Rules!$B$8 -> 66 | U40: emote0 | W40: Planned | X40: 36 | Y40: skill\europe\bard_recovera_mpheal_a
A41: Penguin | B41: Passive 1 | C41: Cold mastery | D41: 1 | E41: Cold Mastery | F41: +{v}% magic attack. | G41: Passive | K41: 3 | L41: 3 | M41: % attack | N41: =Rules!$B$5 -> 10 | O41: =K41+L41*(N41-1) -> 30 | P41: =IF(H41="","",H41+IF(J41="",0,J41)*(N41-1)) | Q41: Spells ignore 10% of magic defense. | R41: +5% magic attack to the owner. | S41: =INDEX(Rules!$B$11:$B$15,MATCH("Row unlock: "&B41,Rules!$A$11:$A$15,0))+(D41-1)*Rules!$B$10 -> 1 | T41: =S41+(N41-1)*Rules!$B$8 -> 37 | V41: Live (raises physical and magical attack). Ranks II and III planned. | W41: Implemented | X41: 37 | Y41: skill\europe\wizard_spiritp_cold_a
...

Sheet Gear
A1: Gear
A2: One equipment family worn by every pet: 3 slots, degrees D1-D9. White base stat from Rules; blues from Affixes.
A4: Degree | B4: Collar base | C4: Harness base | D4: Charm base | E4: Collar: damage +% | F4: Harness: defense +% | G4: Charm: cooldown -% | H4: Min pet level | I4: Collar codename | J4: Collar ID | K4: Harness codename | L4: Harness ID | M4: Charm codename | N4: Charm ID
A5: 1 | B5: Rawhide Collar | C5: Rope Harness | D5: Bone Charm | E5: =A5*Rules!$B$25 -> 2 | F5: =A5*Rules!$B$26 -> 3 | G5: =A5*Rules!$B$27 -> 1 | H5: =Degrees!B5 -> 1 | I5: ITEM_COS_PET_COLLAR_01 | J5: 30101 | K5: ITEM_COS_PET_HARNESS_01 | L5: 30201 | M5: ITEM_COS_PET_CHARM_01 | N5: 30301
A6: 2 | B6: Studded Collar | C6: Leather Harness | D6: Fang Charm | E6: =A6*Rules!$B$25 -> 4 | F6: =A6*Rules!$B$26 -> 6 | G6: =A6*Rules!$B$27 -> 2 | H6: =Degrees!B6 -> 9 | I6: ITEM_COS_PET_COLLAR_02 | J6: 30102 | K6: ITEM_COS_PET_HARNESS_02 | L6: 30202 | M6: ITEM_COS_PET_CHARM_02 | N6: 30302
A7: 3 | B7: Bronze Collar | C7: Studded Harness | D7: Jade Charm | E7: =A7*Rules!$B$25 -> 6 | F7: =A7*Rules!$B$26 -> 9 | G7: =A7*Rules!$B$27 -> 3 | H7: =Degrees!B7 -> 17 | I7: ITEM_COS_PET_COLLAR_03 | J7: 30103 | K7: ITEM_COS_PET_HARNESS_03 | L7: 30203 | M7: ITEM_COS_PET_CHARM_03 | N7: 30303
A8: 4 | B8: Iron Collar | C8: Scale Harness | D8: Amber Charm | E8: =A8*Rules!$B$25 -> 8 | F8: =A8*Rules!$B$26 -> 12 | G8: =A8*Rules!$B$27 -> 4 | H8: =Degrees!B8 -> 25 | I8: ITEM_COS_PET_COLLAR_04 | J8: 30104 | K8: ITEM_COS_PET_HARNESS_04 | L8: 30204 | M8: ITEM_COS_PET_CHARM_04 | N8: 30304
A9: 5 | B9: Steel Collar | C9: Chain Harness | D9: Moonstone Charm | E9: =A9*Rules!$B$25 -> 10 | F9: =A9*Rules!$B$26 -> 15 | G9: =A9*Rules!$B$27 -> 5 | H9: =Degrees!B9 -> 33 | I9: ITEM_COS_PET_COLLAR_05 | J9: 30105 | K9: ITEM_COS_PET_HARNESS_05 | L9: 30205 | M9: ITEM_COS_PET_CHARM_05 | N9: 30305
A10: 6 | B10: Silver Collar | C10: Plate Harness | D10: Sunstone Charm | E10: =A10*Rules!$B$25 -> 12 | F10: =A10*Rules!$B$26 -> 18 | G10: =A10*Rules!$B$27 -> 6 | H10: =Degrees!B10 -> 43 | I10: ITEM_COS_PET_COLLAR_06 | J10: 30106 | K10: ITEM_COS_PET_HARNESS_06 | L10: 30206 | M10: ITEM_COS_PET_CHARM_06 | N10: 30306
A11: 7 | B11: Gilded Collar | C11: Gilded Harness | D11: Starstone Charm | E11: =A11*Rules!$B$25 -> 14 | F11: =A11*Rules!$B$26 -> 21 | G11: =A11*Rules!$B$27 -> 7 | H11: =Degrees!B11 -> 53 | I11: ITEM_COS_PET_COLLAR_07 | J11: 30107 | K11: ITEM_COS_PET_HARNESS_07 | L11: 30207 | M11: ITEM_COS_PET_CHARM_07 | N11: 30307
A12: 8 | B12: Runed Collar | C12: Runed Harness | D12: Spirit Charm | E12: =A12*Rules!$B$25 -> 16 | F12: =A12*Rules!$B$26 -> 24 | G12: =A12*Rules!$B$27 -> 8 | H12: =Degrees!B12 -> 65 | I12: ITEM_COS_PET_COLLAR_08 | J12: 30108 | K12: ITEM_COS_PET_HARNESS_08 | L12: 30208 | M12: ITEM_COS_PET_CHARM_08 | N12: 30308
A13: 9 | B13: Dragonbone Collar | C13: Dragonscale Harness | D13: Primal Charm | E13: =A13*Rules!$B$25 -> 18 | F13: =A13*Rules!$B$26 -> 27 | G13: =A13*Rules!$B$27 -> 9 | H13: =Degrees!B13 -> 77 | I13: ITEM_COS_PET_COLLAR_09 | J13: 30109 | K13: ITEM_COS_PET_HARNESS_09 | L13: 30209 | M13: ITEM_COS_PET_CHARM_09 | N13: 30309
A15: Slots: Collar (offense blues), Harness (defense blues), Charm (utility, skill and proc blues). Item names follow D2: [Prefix] Base [of Suffix], e.g. 'Savage Iron Collar of Storms'.
A16: Rarity: Normal (white, 0 blues), Magic (blue, 1-2), Rare (yellow, 3-5). Odds by degree on Degrees; rare names use two random words (D2 rare naming).

Sheet Degrees
A1: Degrees
A2: Drop chance and blue odds per degree. A monster drops its level band's degree (uniques one higher).
A4: Degree | B4: Monster level from | C4: Monster level to | D4: Drop % per kill (General) | E4: Champion % | F4: Giant % | G4: Unique % | H4: Magic chance | I4: Rare chance | J4: Normal chance | K4: Rare: 3 blues weight | L4: Rare: 4 blues weight | M4: Rare: 5 blues weight | N4: Expected blues per item | O4: Affix tiers available
A5: 1 | B5: 1 | C5: 8 | D5: 0.001 | E5: =MIN(1,D5*Rules!$B$22) -> 0.003 | F5: =MIN(1,D5*Rules!$B$23) -> 0.008 | G5: =MIN(1,D5*Rules!$B$24) -> 0.1 | H5: 0.3 | I5: 0.03 | J5: =1-H5-I5 -> 0.67 | K5: 85 | L5: 13 | M5: 2 | N5: =H5*(1+Rules!$B$20)+I5*(3*K5+4*L5+MIN(5,Rules!$B$19)*M5)/(K5+L5+M5) -> 0.5151 | O5: =COUNTIFS(Affixes!$I$5:$I$104,"<="&A5) -> 14
A6: 2 | B6: 9 | C6: 16 | D6: 0.001 | E6: =MIN(1,D6*Rules!$B$22) -> 0.003 | F6: =MIN(1,D6*Rules!$B$23) -> 0.008 | G6: =MIN(1,D6*Rules!$B$24) -> 0.1 | H6: 0.32 | I6: 0.04 | J6: =1-H6-I6 -> 0.64 | K6: 80 | L6: 16 | M6: 4 | N6: =H6*(1+Rules!$B$20)+I6*(3*K6+4*L6+MIN(5,Rules!$B$19)*M6)/(K6+L6+M6) -> 0.5776 | O6: =COUNTIFS(Affixes!$I$5:$I$104,"<="&A6) -> 18
A7: 3 | B7: 17 | C7: 24 | D7: 0.0011 | E7: =MIN(1,D7*Rules!$B$22) -> 0.0033 | F7: =MIN(1,D7*Rules!$B$23) -> 0.0088 | G7: =MIN(1,D7*Rules!$B$24) -> 0.11 | H7: 0.34 | I7: 0.05 | J7: =1-H7-I7 -> 0.61 | K7: 75 | L7: 20 | M7: 5 | N7: =H7*(1+Rules!$B$20)+I7*(3*K7+4*L7+MIN(5,Rules!$B$19)*M7)/(K7+L7+M7) -> 0.641 | O7: =COUNTIFS(Affixes!$I$5:$I$104,"<="&A7) -> 36
A8: 4 | B8: 25 | C8: 32 | D8: 0.0011 | E8: =MIN(1,D8*Rules!$B$22) -> 0.0033 | F8: =MIN(1,D8*Rules!$B$23) -> 0.0088 | G8: =MIN(1,D8*Rules!$B$24) -> 0.11 | H8: 0.36 | I8: 0.06 | J8: =1-H8-I8 -> 0.58 | K8: 70 | L8: 23 | M8: 7 | N8: =H8*(1+Rules!$B$20)+I8*(3*K8+4*L8+MIN(5,Rules!$B$19)*M8)/(K8+L8+M8) -> 0.7062 | O8: =COUNTIFS(Affixes!$I$5:$I$104,"<="&A8) -> 48
A9: 5 | B9: 33 | C9: 42 | D9: 0.0012 | E9: =MIN(1,D9*Rules!$B$22) -> 0.0036 | F9: =MIN(1,D9*Rules!$B$23) -> 0.0096 | G9: =MIN(1,D9*Rules!$B$24) -> 0.12 | H9: 0.38 | I9: 0.07 | J9: =1-H9-I9 -> 0.55 | K9: 64 | L9: 27 | M9: 9 | N9: =H9*(1+Rules!$B$20)+I9*(3*K9+4*L9+MIN(5,Rules!$B$19)*M9)/(K9+L9+M9) -> 0.7735 | O9: =COUNTIFS(Affixes!$I$5:$I$104,"<="&A9) -> 61
A10: 6 | B10: 43 | C10: 52 | D10: 0.0012 | E10: =MIN(1,D10*Rules!$B$22) -> 0.0036 | F10: =MIN(1,D10*Rules!$B$23) -> 0.0096 | G10: =MIN(1,D10*Rules!$B$24) -> 0.12 | H10: 0.4 | I10: 0.08 | J10: =1-H10-I10 -> 0.52 | K10: 58 | L10: 30 | M10: 12 | N10: =H10*(1+Rules!$B$20)+I10*(3*K10+4*L10+MIN(5,Rules!$B$19)*M10)/(K10+L10+M10) -> 0.8432 | O10: =COUNTIFS(Affixes!$I$5:$I$104,"<="&A10) -> 69
A11: 7 | B11: 53 | C11: 64 | D11: 0.0013 | E11: =MIN(1,D11*Rules!$B$22) -> 0.0039 | F11: =MIN(1,D11*Rules!$B$23) -> 0.0104 | G11: =MIN(1,D11*Rules!$B$24) -> 0.13 | H11: 0.42 | I11: 0.09 | J11: =1-H11-I11 -> 0.49 | K11: 52 | L11: 33 | M11: 15 | N11: =H11*(1+Rules!$B$20)+I11*(3*K11+4*L11+MIN(5,Rules!$B$19)*M11)/(K11+L11+M11) -> 0.9147 | O11: =COUNTIFS(Affixes!$I$5:$I$104,"<="&A11) -> 85
A12: 8 | B12: 65 | C12: 76 | D12: 0.0013 | E12: =MIN(1,D12*Rules!$B$22) -> 0.0039 | F12: =MIN(1,D12*Rules!$B$23) -> 0.0104 | G12: =MIN(1,D12*Rules!$B$24) -> 0.13 | H12: 0.44 | I12: 0.1 | J12: =1-H12-I12 -> 0.46 | K12: 46 | L12: 36 | M12: 18 | N12: =H12*(1+Rules!$B$20)+I12*(3*K12+4*L12+MIN(5,Rules!$B$19)*M12)/(K12+L12+M12) -> 0.988 | O12: =COUNTIFS(Affixes!$I$5:$I$104,"<="&A12) -> 96
A13: 9 | B13: 77 | C13: 90 | D13: 0.0014 | E13: =MIN(1,D13*Rules!$B$22) -> 0.0042 | F13: =MIN(1,D13*Rules!$B$23) -> 0.0112 | G13: =MIN(1,D13*Rules!$B$24) -> 0.14 | H13: 0.46 | I13: 0.12 | J13: =1-H13-I13 -> 0.42 | K13: 40 | L13: 38 | M13: 22 | N13: =H13*(1+Rules!$B$20)+I13*(3*K13+4*L13+MIN(5,Rules!$B$19)*M13)/(K13+L13+M13) -> 1.1024 | O13: =COUNTIFS(Affixes!$I$5:$I$104,"<="&A13) -> 100
A15: Tier rule (D2 alvl): an affix tier can roll when its Min degree <= the item's degree; Affixes > Weight picks among the eligible tiers, so higher degrees reach better tiers and, via rare odds, more blues.
A16: Pet level to wear: Min pet level = degree's Monster level from (column B), so pets and owners progress together.

Sheet Affixes
A1: Affixes (blues)
A2: One affix per Group per item; a Tier rolls when its Min degree <= item degree. {v} is a roll between Value min and max.
A4: Affix ID | B4: Name | C4: Kind | D4: Group | E4: Category | F4: Slots | G4: Effect ({v}) | H4: Tier | I4: Min degree | J4: Value min | K4: Value max | L4: Unit | M4: Weight | N4: Pets | O4: Engine notes | P4: Status | Q4: Code
A5: DmgPhys1 | B5: Savage | C5: Prefix | D5: DmgPhys | E5: Offense | F5: Collar, Charm | G5: +{v}% physical damage | H5: 1 | I5: 1 | J5: 5 | K5: 10 | L5: % | M5: 100 | N5: All | O5: Attack multiplier (as Predator). | P5: Implemented | Q5: 1
A6: DmgPhys2 | B6: Brutal | C6: Prefix | D6: DmgPhys | E6: Offense | F6: Collar, Charm | G6: +{v}% physical damage | H6: 2 | I6: 3 | J6: 11 | K6: 20 | L6: % | M6: 85 | N6: All | O6: Attack multiplier (as Predator). | P6: Implemented | Q6: 2
A7: DmgPhys3 | B7: Ferocious | C7: Prefix | D7: DmgPhys | E7: Offense | F7: Collar, Charm | G7: +{v}% physical damage | H7: 3 | I7: 5 | J7: 21 | K7: 35 | L7: % | M7: 70 | N7: All | O7: Attack multiplier (as Predator). | P7: Implemented | Q7: 3
A8: DmgPhys4 | B8: Merciless | C8: Prefix | D8: DmgPhys | E8: Offense | F8: Collar, Charm | G8: +{v}% physical damage | H8: 4 | I8: 7 | J8: 36 | K8: 50 | L8: % | M8: 55 | N8: All | O8: Attack multiplier (as Predator). | P8: Implemented | Q8: 4
A9: DmgMag1 | B9: Sorcerous | C9: Prefix | D9: DmgMag | E9: Offense | F9: Collar, Charm | G9: +{v}% magic damage | H9: 1 | I9: 1 | J9: 5 | K9: 10 | L9: % | M9: 100 | N9: All | O9: Magic attack multiplier. | P9: Implemented | Q9: 5
A10: DmgMag2 | B10: Arcane | C10: Prefix | D10: DmgMag | E10: Offense | F10: Collar, Charm | G10: +{v}% magic damage | H10: 2 | I10: 3 | J10: 11 | K10: 20 | L10: % | M10: 85 | N10: All | O10: Magic attack multiplier. | P10: Implemented | Q10: 6
A11: DmgMag3 | B11: Mystic | C11: Prefix | D11: DmgMag | E11: Offense | F11: Collar, Charm | G11: +{v}% magic damage | H11: 3 | I11: 5 | J11: 21 | K11: 35 | L11: % | M11: 70 | N11: All | O11: Magic attack multiplier. | P11: Implemented | Q11: 7
A12: DmgMag4 | B12: Eldritch | C12: Prefix | D12: DmgMag | E12: Offense | F12: Collar, Charm | G12: +{v}% magic damage | H12: 4 | I12: 7 | J12: 36 | K12: 50 | L12: % | M12: 55 | N12: All | O12: Magic attack multiplier. | P12: Implemented | Q12: 8
A13: Crit1 | B13: Keen | C13: Prefix | D13: Crit | E13: Offense | F13: Collar | G13: +{v}% critical chance | H13: 1 | I13: 2 | J13: 2 | K13: 3 | L13: % | M13: 100 | N13: All | O13: Critical roll exists. | P13: Implemented | Q13: 9
A14: Crit2 | B14: Deadly | C14: Prefix | D14: Crit | E14: Offense | F14: Collar | G14: +{v}% critical chance | H14: 2 | I14: 4 | J14: 4 | K14: 6 | L14: % | M14: 85 | N14: All | O14: Critical roll exists. | P14: Implemented | Q14: 10
A15: Crit3 | B15: Lethal | C15: Prefix | D15: Crit | E15: Offense | F15: Collar | G15: +{v}% critical chance | H15: 3 | I15: 6 | J15: 7 | K15: 9 | L15: % | M15: 70 | N15: All | O15: Critical roll exists. | P15: Implemented | Q15: 11
A16: Fire1 | B16: Smoldering | C16: Prefix | D16: Fire | E16: Offense | F16: Collar, Harness | G16: Adds {v} fire damage; 5% chance to burn | H16: 1 | I16: 1 | J16: 3 | K16: 6 | L16: damage | M16: 100 | N16: All | O16: Native burn status. | P16: Implemented | Q16: 12
... A104: Phoenix1 | B104: of the Phoenix | C104: Suffix | D104: Phoenix | E104: Proc | F104: Charm | G104: {v}% chance to revive at 30% HP on death (once per 5 min) | H104: 1 | I104: 8 | J104: 20 | K104: 30 | L104: % | M104: 10 | N104: All | O104: Pet death path; very rare. | P104: Planned | Q104: 100
A106: Affixes per slot (formula):
A107: Collar | B107: =COUNTIF($F$5:$F$104,"*Collar*") -> 46
A108: Harness | B108: =COUNTIF($F$5:$F$104,"*Harness*") -> 56
A109: Charm | B109: =COUNTIF($F$5:$F$104,"*Charm*") -> 53

Sheet Procs
A1: Procs
A2: Skills that affixes ('chance to cast') and some pet skills call. Level comes from the affix (2 x degree) or the pet skill level.
A4: Proc | B4: Effect ({v}) | C4: Value at level 1 | D4: Value per level | E4: Value at level 18 (D9) | F4: Unit | G4: Radius / targets | H4: Visual reuse | I4: Engine notes
A5: Chain Lightning | B5: Lightning that jumps between enemies for {v} damage each. | C5: 20 | D5: 15 | E5: =C5+D5*17 -> 275 | F5: damage | G5: 3 + level/3 jumps, 8 m | H5: Native lightning chain skill effect | I5: Multi-target chain; shock status.
A6: Frost Nova | B6: Cold burst around the pet for {v} damage, frostbite 3 s. | C6: 15 | D6: 12 | E6: =C6+D6*17 -> 219 | F6: damage | G6: 5 m | H6: Native cold area effect | I6: Area candidates exist.
A7: Fire Burst | B7: Flames on the target for {v} damage, burn 4 s. | C7: 18 | D7: 14 | E7: =C7+D7*17 -> 256 | F7: damage | G7: 3 m around target | H7: Native fire burst effect | I7: Burn status exists.
A8: Poison Cloud | B8: Cloud around the pet: {v} poison damage over 5 s. | C8: 25 | D8: 18 | E8: =C8+D8*17 -> 331 | F8: damage | G8: 4 m | H8: Native poison effect | I8: Poison status exists.
A9: Terror | B9: Up to {v} monsters near the pet flee for 2 s. | C9: 2 | D9: 0.25 | E9: =C9+D9*17 -> 6.25 | F9: monsters | G9: 6 m | H9: Pet emote0 + fear icon | I9: Flee AI state (shared with Terrifying Howl).
A10: Mend | B10: Heals the owner {v}% of max HP. | C10: 3 | D10: 0.4 | E10: =C10+D10*17 -> 9.8 | F10: % HP | G10: Owner | H10: Native heal effect | I10: Heal on the owner.
A11: Corpse Burst | B11: The slain monster explodes for {v}% of its max HP to enemies within 4 m. | C11: 20 | D11: 2 | E11: =C11+D11*17 -> 54 | F11: % of HP | G11: 4 m | H11: Native explosion effect | I11: On-kill hook in kill settlement.
